import scala.concurrent.Future

//Monads let you compose functions that donâ€™t compose well, such as functions that have side effects.

//Futures

// Make 3 sequential async calls
for {
  foo <- WS.url("http://foo.com").get()
  bar <- WS.url("http://bar.com").get()
  baz <- WS.url("http://baz.com").get()
} yield {
  // Build a Result using foo, bar, and baz

  Ok(...)
}

// Make 3 parallel async calls
val fooFuture = WS.url("http://foo.com").get()
val barFuture = WS.url("http://bar.com").get()
val bazFuture = WS.url("http://baz.com").get()

for {
  foo <- fooFuture
  bar <- barFuture
  baz <- bazFuture
} yield {
  // Build a Result using foo, bar, and baz

  Ok(...)
}

// Handle Exceptions in Futures by logging them and returning a fallback value
def withErrorHandling[T](f: Future[T], fallback: T): Future[T] = {
  f.recover { case t: Throwable =>
    println("Something went wrong!", t)
    fallback
  }
}

val myFuture = someAsyncIO()
val myFutureWithFallback = withErrorHandling(myFuture, "fallback value")



import scala.util.{Failure, Success, Try}

//Try/ Monad
//Try will let you recover from exceptions at any point in the chain, so you can defer recovery to the end

val sum = (for {
  int1 <- Try(Integer.parseInt("one"))
  int2 <- Try(Integer.parseInt("two"))
} yield {
    int1 + int2
  }) recover {
    case e => 0
  }

//Processing a seq of Trys
val maybeInts:Seq[scala.util.Try[Int]] = List(
  Success(1),
  Success(2),
  Failure(new java.lang.NumberFormatException("""For input string: "a""")),
  Success(3),
  Success(4))
maybeInts foreach { case Success(x) => println(x) case Failure(y) =>println(y) }